'use strict';
/*------------------------------------------------------------------------------
Full description at: https://github.com/HackYourFuture/Homework/tree/main/3-UsingAPIs/Week1#exercise-3-roll-a-die

- Run the unmodified program and confirm that problem described occurs.
- Refactor the `rollDie()` function from callback-based to returning a
  promise.
- Change the calls to `callback()` to calls to `resolve()` and `reject()`.
- Refactor the code that call `rollDie()` to use the promise it returns.
- Does the problem described above still occur? If not, what would be your
  explanation? Add your answer as a comment to be bottom of the file.
------------------------------------------------------------------------------*/
function rollDie() {
  return new Promise((resolve, reject) => {
    // Compute a random number of rolls (3-10) that the die MUST complete
    const randomRollsToDo = Math.floor(Math.random() * 8) + 3;
    console.log(`Die scheduled for ${randomRollsToDo} rolls...`);

    const rollOnce = (roll) => {
      // Compute a random die value for the current roll
      const value = Math.floor(Math.random() * 6) + 1;
      console.log(`Die value is now: ${value}`);

      // Use callback to notify that the die rolled off the table after 6 rolls
      if (roll > 6) {
        reject(new Error('Oops... Die rolled off the table.'));
      }

      // Use callback to communicate the final die value once finished rolling
      if (roll === randomRollsToDo) {
        resolve(`Success! Die settled on ${value}.`);
      }

      // Schedule the next roll todo until no more rolls to do
      if (roll < randomRollsToDo) {
        setTimeout(() => rollOnce(roll + 1), 500);
      }
    };

    // Start the initial roll
    rollOnce(1);
  });
}

function main() {
  rollDie()
    .then((message) => console.log(message))
    .catch((error) => console.log(error.message));
}

// ! Do not change or remove the code below
if (process.env.NODE_ENV !== 'test') {
  main();
}
module.exports = rollDie;

// After we switched the callbacks to the promises there is no problem anymore.
// Because we have a special catch method in the promise, we can catch the error in the the promise.
// In this case, the catch is not called on the original promise, it is called on the promise returned by then method.
// That's why the promise ends when the catch fulfills its obligation and we don't see the resolve message.
